Workbook

Sheet 得獎名單
A1: 序號 | B1: 獎項 | C1: 金額 | D1: 工號 | E1: 姓名 | F1: 單位
A2: 1 | B2: 六獎-現金 | C2: 2000 | D2: 001 | E2: =IFERROR(VLOOKUP(得獎名單!D2,人員名單資料庫!$A$2:$C$33,3,FALSE),"") -> A01 | F2: =IFERROR(VLOOKUP(得獎名單!D2,人員名單資料庫!$A$2:$C$33,2,FALSE),"") -> A
A3: 2 | B3: 六獎-現金 | C3: 2000 | D3: 002 | E3: =IFERROR(VLOOKUP(得獎名單!D3,人員名單資料庫!$A$2:$C$33,3,FALSE),"") -> B01 | F3: =IFERROR(VLOOKUP(得獎名單!D3,人員名單資料庫!$A$2:$C$33,2,FALSE),"") -> B
A4: 3 | B4: 六獎-現金 | C4: 2000 | D4: 003 | E4: =IFERROR(VLOOKUP(得獎名單!D4,人員名單資料庫!$A$2:$C$33,3,FALSE),"") -> C01 | F4: =IFERROR(VLOOKUP(得獎名單!D4,人員名單資料庫!$A$2:$C$33,2,FALSE),"") -> C
A5: 4 | B5: 六獎-現金 | C5: 2000 | D5: 025 | E5: =IFERROR(VLOOKUP(得獎名單!D5,人員名單資料庫!$A$2:$C$33,3,FALSE),"") -> A05 | F5: =IFERROR(VLOOKUP(得獎名單!D5,人員名單資料庫!$A$2:$C$33,2,FALSE),"") -> A
A6: 5 | B6: 六獎-現金 | C6: 2000 | D6: 026 | E6: =IFERROR(VLOOKUP(得獎名單!D6,人員名單資料庫!$A$2:$C$33,3,FALSE),"") -> B05 | F6: =IFERROR(VLOOKUP(得獎名單!D6,人員名單資料庫!$A$2:$C$33,2,FALSE),"") -> B
A7: 6 | B7: 六獎-現金 | C7: 2000 | D7: 027 | E7: =IFERROR(VLOOKUP(得獎名單!D7,人員名單資料庫!$A$2:$C$33,3,FALSE),"") -> C05 | F7: =IFERROR(VLOOKUP(得獎名單!D7,人員名單資料庫!$A$2:$C$33,2,FALSE),"") -> C
A8: 7 | B8: 六獎-現金 | C8: 2000 | D8: 028 | E8: =IFERROR(VLOOKUP(得獎名單!D8,人員名單資料庫!$A$2:$C$33,3,FALSE),"") -> A06 | F8: =IFERROR(VLOOKUP(得獎名單!D8,人員名單資料庫!$A$2:$C$33,2,FALSE),"") -> A
A9: 8 | B9: 六獎-現金 | C9: 2000 | D9: 029 | E9: =IFERROR(VLOOKUP(得獎名單!D9,人員名單資料庫!$A$2:$C$33,3,FALSE),"") -> B06 | F9: =IFERROR(VLOOKUP(得獎名單!D9,人員名單資料庫!$A$2:$C$33,2,FALSE),"") -> B
A10: 9 | B10: 六獎-現金 | C10: 2000 | D10: 030 | E10: =IFERROR(VLOOKUP(得獎名單!D10,人員名單資料庫!$A$2:$C$33,3,FALSE),"") -> C06 | F10: =IFERROR(VLOOKUP(得獎名單!D10,人員名單資料庫!$A$2:$C$33,2,FALSE),"") -> C
A11: 10 | B11: 六獎-現金 | C11: 2000 | D11: 031 | E11: =IFERROR(VLOOKUP(得獎名單!D11,人員名單資料庫!$A$2:$C$33,3,FALSE),"") -> A06 | F11: =IFERROR(VLOOKUP(得獎名單!D11,人員名單資料庫!$A$2:$C$33,2,FALSE),"") -> A
A12: 11 | B12: 六獎-現金 | C12: 2000 | D12: 032 | E12: =IFERROR(VLOOKUP(得獎名單!D12,人員名單資料庫!$A$2:$C$33,3,FALSE),"") -> B06 | F12: =IFERROR(VLOOKUP(得獎名單!D12,人員名單資料庫!$A$2:$C$33,2,FALSE),"") -> B
A13: 12 | B13: 六獎-現金 | C13: 2000 | E13: =IFERROR(VLOOKUP(得獎名單!D13,人員名單資料庫!$A$2:$C$33,3,FALSE),"") | F13: =IFERROR(VLOOKUP(得獎名單!D13,人員名單資料庫!$A$2:$C$33,2,FALSE),"")
A14: 13 | B14: 六獎-現金 | C14: 2000 | E14: =IFERROR(VLOOKUP(得獎名單!D14,人員名單資料庫!$A$2:$C$33,3,FALSE),"") | F14: =IFERROR(VLOOKUP(得獎名單!D14,人員名單資料庫!$A$2:$C$33,2,FALSE),"")
A15: 14 | B15: 六獎-現金 | C15: 2000 | E15: =IFERROR(VLOOKUP(得獎名單!D15,人員名單資料庫!$A$2:$C$33,3,FALSE),"") | F15: =IFERROR(VLOOKUP(得獎名單!D15,人員名單資料庫!$A$2:$C$33,2,FALSE),"")
A16: 15 | B16: 六獎-現金 | C16: 2000 | E16: =IFERROR(VLOOKUP(得獎名單!D16,人員名單資料庫!$A$2:$C$33,3,FALSE),"") | F16: =IFERROR(VLOOKUP(得獎名單!D16,人員名單資料庫!$A$2:$C$33,2,FALSE),"")
A17: 16 | B17: 六獎-現金 | C17: 2000 | E17: =IFERROR(VLOOKUP(得獎名單!D17,人員名單資料庫!$A$2:$C$33,3,FALSE),"") | F17: =IFERROR(VLOOKUP(得獎名單!D17,人員名單資料庫!$A$2:$C$33,2,FALSE),"")
A18: 17 | B18: 六獎-現金 | C18: 2000 | E18: =IFERROR(VLOOKUP(得獎名單!D18,人員名單資料庫!$A$2:$C$33,3,FALSE),"") | F18: =IFERROR(VLOOKUP(得獎名單!D18,人員名單資料庫!$A$2:$C$33,2,FALSE),"")
A19: 18 | B19: 六獎-現金 | C19: 2000 | E19: =IFERROR(VLOOKUP(得獎名單!D19,人員名單資料庫!$A$2:$C$33,3,FALSE),"") | F19: =IFERROR(VLOOKUP(得獎名單!D19,人員名單資料庫!$A$2:$C$33,2,FALSE),"")
A20: 19 | B20: 六獎-現金 | C20: 2000 | E20: =IFERROR(VLOOKUP(得獎名單!D20,人員名單資料庫!$A$2:$C$33,3,FALSE),"") | F20: =IFERROR(VLOOKUP(得獎名單!D20,人員名單資料庫!$A$2:$C$33,2,FALSE),"")
A21: 20 | B21: 六獎-現金 | C21: 2000 | E21: =IFERROR(VLOOKUP(得獎名單!D21,人員名單資料庫!$A$2:$C$33,3,FALSE),"") | F21: =IFERROR(VLOOKUP(得獎名單!D21,人員名單資料庫!$A$2:$C$33,2,FALSE),"")
A22: 21 | B22: 六獎-現金 | C22: 2000 | E22: =IFERROR(VLOOKUP(得獎名單!D22,人員名單資料庫!$A$2:$C$33,3,FALSE),"") | F22: =IFERROR(VLOOKUP(得獎名單!D22,人員名單資料庫!$A$2:$C$33,2,FALSE),"")
A23: 22 | B23: 六獎-現金 | C23: 2000 | E23: =IFERROR(VLOOKUP(得獎名單!D23,人員名單資料庫!$A$2:$C$33,3,FALSE),"") | F23: =IFERROR(VLOOKUP(得獎名單!D23,人員名單資料庫!$A$2:$C$33,2,FALSE),"")
A24: 23 | B24: 六獎-現金 | C24: 2000 | E24: =IFERROR(VLOOKUP(得獎名單!D24,人員名單資料庫!$A$2:$C$33,3,FALSE),"") | F24: =IFERROR(VLOOKUP(得獎名單!D24,人員名單資料庫!$A$2:$C$33,2,FALSE),"")
... A51: 50 | B51: 六獎-現金 | C51: 2000 | E51: =IFERROR(VLOOKUP(得獎名單!D51,人員名單資料庫!$A$2:$C$33,3,FALSE),"") | F51: =IFERROR(VLOOKUP(得獎名單!D51,人員名單資料庫!$A$2:$C$33,2,FALSE),"")
A52: 1 | B52: 四獎 | C52: 6000 | D52: 004 | E52: =IFERROR(VLOOKUP(得獎名單!D52,人員名單資料庫!$A$2:$C$33,3,FALSE),"") -> A02 | F52: =IFERROR(VLOOKUP(得獎名單!D52,人員名單資料庫!$A$2:$C$33,2,FALSE),"") -> A
A53: 2 | B53: 四獎 | C53: 6000 | D53: 005 | E53: =IFERROR(VLOOKUP(得獎名單!D53,人員名單資料庫!$A$2:$C$33,3,FALSE),"") -> B02 | F53: =IFERROR(VLOOKUP(得獎名單!D53,人員名單資料庫!$A$2:$C$33,2,FALSE),"") -> B
A54: 3 | B54: 四獎 | C54: 6000 | D54: 006 | E54: =IFERROR(VLOOKUP(得獎名單!D54,人員名單資料庫!$A$2:$C$33,3,FALSE),"") -> C02 | F54: =IFERROR(VLOOKUP(得獎名單!D54,人員名單資料庫!$A$2:$C$33,2,FALSE),"") -> C
A55: 4 | B55: 四獎 | C55: 6000 | D55: 007 | E55: =IFERROR(VLOOKUP(得獎名單!D55,人員名單資料庫!$A$2:$C$33,3,FALSE),"") -> A02 | F55: =IFERROR(VLOOKUP(得獎名單!D55,人員名單資料庫!$A$2:$C$33,2,FALSE),"") -> A
A56: 5 | B56: 四獎 | C56: 6000 | D56: 008 | E56: =IFERROR(VLOOKUP(得獎名單!D56,人員名單資料庫!$A$2:$C$33,3,FALSE),"") -> B02 | F56: =IFERROR(VLOOKUP(得獎名單!D56,人員名單資料庫!$A$2:$C$33,2,FALSE),"") -> B
A57: 6 | B57: 四獎 | C57: 6000 | D57: 009 | E57: =IFERROR(VLOOKUP(得獎名單!D57,人員名單資料庫!$A$2:$C$33,3,FALSE),"") -> C02 | F57: =IFERROR(VLOOKUP(得獎名單!D57,人員名單資料庫!$A$2:$C$33,2,FALSE),"") -> C
A58: 7 | B58: 四獎 | C58: 6000 | E58: =IFERROR(VLOOKUP(得獎名單!D58,人員名單資料庫!$A$2:$C$33,3,FALSE),"") | F58: =IFERROR(VLOOKUP(得獎名單!D58,人員名單資料庫!$A$2:$C$33,2,FALSE),"")
A59: 8 | B59: 四獎 | C59: 6000 | E59: =IFERROR(VLOOKUP(得獎名單!D59,人員名單資料庫!$A$2:$C$33,3,FALSE),"") | F59: =IFERROR(VLOOKUP(得獎名單!D59,人員名單資料庫!$A$2:$C$33,2,FALSE),"")
A60: 9 | B60: 四獎 | C60: 6000 | E60: =IFERROR(VLOOKUP(得獎名單!D60,人員名單資料庫!$A$2:$C$33,3,FALSE),"") | F60: =IFERROR(VLOOKUP(得獎名單!D60,人員名單資料庫!$A$2:$C$33,2,FALSE),"")
A61: 10 | B61: 四獎 | C61: 6000 | E61: =IFERROR(VLOOKUP(得獎名單!D61,人員名單資料庫!$A$2:$C$33,3,FALSE),"") | F61: =IFERROR(VLOOKUP(得獎名單!D61,人員名單資料庫!$A$2:$C$33,2,FALSE),"")
A62: 11 | B62: 四獎 | C62: 6000 | E62: =IFERROR(VLOOKUP(得獎名單!D62,人員名單資料庫!$A$2:$C$33,3,FALSE),"") | F62: =IFERROR(VLOOKUP(得獎名單!D62,人員名單資料庫!$A$2:$C$33,2,FALSE),"")
A63: 12 | B63: 四獎 | C63: 6000 | E63: =IFERROR(VLOOKUP(得獎名單!D63,人員名單資料庫!$A$2:$C$33,3,FALSE),"") | F63: =IFERROR(VLOOKUP(得獎名單!D63,人員名單資料庫!$A$2:$C$33,2,FALSE),"")
A64: 13 | B64: 四獎 | C64: 6000 | E64: =IFERROR(VLOOKUP(得獎名單!D64,人員名單資料庫!$A$2:$C$33,3,FALSE),"") | F64: =IFERROR(VLOOKUP(得獎名單!D64,人員名單資料庫!$A$2:$C$33,2,FALSE),"")
A65: 14 | B65: 四獎 | C65: 6000 | E65: =IFERROR(VLOOKUP(得獎名單!D65,人員名單資料庫!$A$2:$C$33,3,FALSE),"") | F65: =IFERROR(VLOOKUP(得獎名單!D65,人員名單資料庫!$A$2:$C$33,2,FALSE),"")
A66: 15 | B66: 四獎 | C66: 6000 | E66: =IFERROR(VLOOKUP(得獎名單!D66,人員名單資料庫!$A$2:$C$33,3,FALSE),"") | F66: =IFERROR(VLOOKUP(得獎名單!D66,人員名單資料庫!$A$2:$C$33,2,FALSE),"")
...

Sheet 系統設定
A1: A (設定項目) | B1: B (設定值) | C1: C (說明 - 選填)
A2: 設定項目 | B2: 設定內容 | C2: 說明
A3: 活動標題 | B3: 2026 尾牙摸彩 | C3: 顯示在大螢幕最上方的標題
A4: 活動副標題 | B4: 馬到成功・開運大吉 | C4: 修改副標題
A5: 滾動速度 | B5: 0.5 | C5: 數字越大滾越快 (建議 0.5 ~ 3.0)
A6: 更新頻率 | B6: 5 | C6: 幾秒鐘讀取一次檔案
A7: 欄位-獎項 | B7: 獎項 | C7: 指定 Excel 裡的獎項欄位名稱
A8: 欄位-姓名 | B8: 姓名 | C8: 指定 Excel 裡的姓名欄位名稱
A9: 欄位-單位 | B9: 單位 | C9: 指定 Excel 裡的單位欄位名稱
A10: 欄位-工號 | B10: 工號 | C10: 指定 Excel 裡的工號欄位名稱

Sheet 人員名單資料庫
A1: 員工編號 | B1: 單位名稱 | C1: 中文姓名
A2: 001 | B2: A | C2: A01
A3: 002 | B3: B | C3: B01
A4: 003 | B4: C | C4: C01
A5: 004 | B5: A | C5: A02
A6: 005 | B6: B | C6: B02
A7: 006 | B7: C | C7: C02
A8: 007 | B8: A | C8: A02
A9: 008 | B9: B | C9: B02
A10: 009 | B10: C | C10: C02
A11: 010 | B11: A | C11: A03
A12: 011 | B12: B | C12: B03
... A33: 032 | B33: B | C33: B06
